<?xml version="1.0" encoding="utf-8"?>
<!-- <robot name="piper_arm" xmlns:xacro="http://www.ros.org/wiki/xacro"> -->
<robot  xmlns:xacro="http://www.ros.org/wiki/xacro" >

    <!-- MESHES -->
    <xacro:property name="arm_base_link" value="package://robot_description/meshes/arm_base_link.STL" />
    <xacro:property name="arm_link1"     value="package://robot_description/meshes/arm_link1.STL" />
    <xacro:property name="arm_link2"     value="package://robot_description/meshes/arm_link2.STL" />
    <xacro:property name="arm_link3"     value="package://robot_description/meshes/arm_link3.STL" />
    <xacro:property name="arm_link4"     value="package://robot_description/meshes/arm_link4.STL" />
    <xacro:property name="arm_link5"     value="package://robot_description/meshes/arm_link5.STL" />
    <xacro:property name="arm_link6"     value="package://robot_description/meshes/arm_link6.STL" />


    <!-- LINKS -->

    <!-- Link base -->
    <link name="base_link">
        <inertial>
            <origin xyz="-0.00473641164191482 2.56829134630247E-05 0.041451518036016" rpy="0 0 0"/>
            <mass value="1.02"/>
            <inertia ixx="0.00267433" ixy="-0.00000073" ixz="-0.00017389"
                     iyy="0.00282612" iyz="0.0000004"   izz="0.00089624"/>
        </inertial>
        <visual>
            <origin xyz="0 0 0" rpy="0 0 0"/>
            <geometry>
                <mesh filename="${arm_base_link}"/>
            </geometry>
            <material name="piper_grey">
                <color rgba="0.792 0.820 0.933 1"/>
            </material>
        </visual>
        <collision>
            <origin xyz="0 0 0" rpy="0 0 0"/>
            <geometry>
                <mesh filename="${arm_base_link}"/>
            </geometry>
        </collision>
    </link>

    <!-- Link 1 -->
    <link name="link1">
        <inertial>
            <origin xyz="0.000121504734057468 0.000104632162460536 -0.00438597309559853" rpy="0 0 0"/>
            <mass value="0.71"/>
            <inertia ixx="0.00048916" ixy="-0.00000036" ixz="-0.00000224"
                     iyy="0.00040472" iyz="-0.00000242" izz="0.00043982"/>
        </inertial>
        <visual>
            <origin xyz="0 0 0" rpy="0 0 0"/>
            <geometry>
                <mesh filename="${arm_link1}"/>
            </geometry>
            <material name="piper_grey"/>
        </visual>
        <collision>
            <origin xyz="0 0 0" rpy="0 0 0"/>
            <geometry>
                <mesh filename="${arm_link1}"/>
            </geometry>
        </collision>
    </link>

    <!-- Link 2 -->
    <link name="link2">
        <inertial>
            <origin xyz="0.198666145229743 -0.010926924140076 0.00142121714502687" rpy="0 0 0"/>
            <mass value="1.17"/>
            <inertia ixx="0.00116918" ixy="-0.00180037" ixz="0.00025146"
                     iyy="0.06785384" iyz="-0.00000455" izz="0.06774489"/>
        </inertial>
        <visual>
            <origin xyz="0 0 0" rpy="0 0 0"/>
            <geometry>
                <mesh filename="${arm_link2}"/>
            </geometry>
            <material name="piper_grey"/>
        </visual>
        <collision>
            <origin xyz="0 0 0" rpy="0 0 0"/>
            <geometry>
                <mesh filename="${arm_link2}"/>
            </geometry>
        </collision>
    </link>

    <!-- Link 3 -->
    <link name="link3">
        <inertial>
            <origin xyz="-0.0202737662122021 -0.133914995944595 -0.000458682652737356" rpy="0 0 0"/>
            <mass value="0.5"/>
            <inertia ixx="0.01361711" ixy="0.00165794" ixz="-0.00000048"
                     iyy="0.00045024" iyz="-0.00000045" izz="0.01380322"/>
        </inertial>
        <visual>
            <origin xyz="0 0 0" rpy="0 0 0"/>
            <geometry>
                <mesh filename="${arm_link3}"/>
            </geometry>
            <material name="piper_grey"/>
        </visual>
        <collision>
            <origin xyz="0 0 0" rpy="0 0 0"/>
            <geometry>
                <mesh filename="${arm_link3}"/>
            </geometry>
        </collision>
    </link>

    <!-- Link 4 -->
    <link name="link4">
        <inertial>
            <origin xyz="-9.66635791618542E-05 0.000876064475651083 -0.00496880904640868" rpy="0 0 0"/>
            <mass value="0.38"/>
            <inertia ixx="0.00018501" ixy="0.00000054" ixz="0.00000120"
                     iyy="0.00018965" iyz="-0.00000841" izz="0.00015484"/>
        </inertial>
        <visual>
            <origin xyz="0 0 0" rpy="0 0 0"/>
            <geometry>
                <mesh filename="${arm_link4}"/>
            </geometry>
            <material name="piper_grey"/>
        </visual>
        <collision>
            <origin xyz="0 0 0" rpy="0 0 0"/>
            <geometry>
                <mesh filename="${arm_link4}"/>
            </geometry>
        </collision>
    </link>

    <!-- Link 5 -->
    <link name="link5">
        <inertial>
            <origin xyz="-4.10554118924211E-05 -0.0566486692356075 -0.0037205791677906" rpy="0 0 0"/>
            <mass value="0.383"/>
            <inertia ixx="0.00166169" ixy="0.00000006" ixz="-0.00000007"
                     iyy="0.00018510" iyz="0.00001026" izz="0.00164321"/>
        </inertial>
        <visual>
            <origin xyz="0 0 0" rpy="0 0 0"/>
            <geometry>
                <mesh filename="${arm_link5}"/>
            </geometry>
            <material name="piper_grey"/>
        </visual>
        <collision>
            <origin xyz="0 0 0" rpy="0 0 0"/>
            <geometry>
                <mesh filename="${arm_link5}"/>
            </geometry>
        </collision>
    </link>

    <!-- Link 6 (end-effector flange) -->
    <link name="link6">
        <inertial>
            <origin xyz="-8.82590762930069E-05 9.0598378529832E-06 -0.002" rpy="0 0 0"/>
            <mass value="0.007"/>
            <inertia ixx="5.73015540542155E-07" ixy="-1.98305403089247E-22" ixz="-7.2791893904596E-23"
                     iyy="5.73015540542155E-07" iyz="-3.4146026640245E-24"  izz="1.06738869138926E-06"/>
        </inertial>
        <visual>
            <origin xyz="0 0 0" rpy="0 0 0"/>
            <geometry>
                <mesh filename="${arm_link6}"/>
            </geometry>
            <material name="piper_light_grey">
                <color rgba="0.898 0.918 0.929 1"/>
            </material>
        </visual>
        <collision>
            <origin xyz="0 0 0" rpy="0 0 0"/>
            <geometry>
                <mesh filename="${arm_link6}"/>
            </geometry>
        </collision>
    </link>


    <!-- JOINTS -->

    <!-- J1 – base → link1  (rotation: yaw) -->
    <joint name="joint1" type="revolute">
        <origin xyz="0 0 0.123" rpy="0 0 0"/>
        <parent link="base_link"/>
        <child  link="link1"/>
        <axis xyz="0 0 1"/>
        <limit effort="100" velocity="5" lower="-2.618" upper="2.168"/>
    </joint>

    <!-- J2 – link1 → link2  (shoulder lift) -->
    <joint name="joint2" type="revolute">
        <origin xyz="0 0 0" rpy="1.5708 -0.1359 -3.1416"/>
        <parent link="link1"/>
        <child  link="link2"/>
        <axis xyz="0 0 1"/>
        <limit effort="100" velocity="5" lower="0" upper="3.14"/>
    </joint>

    <!-- J3 – link2 → link3  (elbow) -->
    <joint name="joint3" type="revolute">
        <origin xyz="0.28503 0 0" rpy="0 0 -1.7939"/>
        <parent link="link2"/>
        <child  link="link3"/>
        <axis xyz="0 0 1"/>
        <limit effort="100" velocity="5" lower="-2.967" upper="0"/>
    </joint>

    <!-- J4 – link3 → link4  (wrist pitch) -->
    <joint name="joint4" type="revolute">
        <origin xyz="-0.021984 -0.25075 0" rpy="1.5708 0 0"/>
        <parent link="link3"/>
        <child  link="link4"/>
        <axis xyz="0 0 1"/>
        <limit effort="100" velocity="5" lower="-1.745" upper="1.745"/>
    </joint>

    <!-- J5 – link4 → link5  (wrist roll) -->
    <joint name="joint5" type="revolute">
        <origin xyz="0 0 0" rpy="-1.5708 0 0"/>
        <parent link="link4"/>
        <child  link="link5"/>
        <axis xyz="0 0 1"/>
        <limit effort="100" velocity="5" lower="-1.22" upper="1.22"/>
    </joint>

    <!-- J6 – link5 → link6  (end-effector flange) -->
    <joint name="joint6" type="revolute">
        <origin xyz="8.8259E-05 -0.091 0" rpy="1.5708 0 0"/>
        <parent link="link5"/>
        <child  link="link6"/>
        <axis xyz="0 0 1"/>
        <limit effort="100" velocity="3" lower="-2.0944" upper="2.0944"/>
    </joint>


    <!-- TRANSMISSIONS -->

    <transmission name="joint1_trans">
        <type>transmission_interface/SimpleTransmission</type>
        <joint name="joint1">
            <hardwareInterface>hardware_interface/PositionJointInterface</hardwareInterface>
        </joint>
        <actuator name="motor1">
            <hardwareInterface>hardware_interface/PositionJointInterface</hardwareInterface>
            <mechanicalReduction>1</mechanicalReduction>
        </actuator>
    </transmission>

    <transmission name="joint2_trans">
        <type>transmission_interface/SimpleTransmission</type>
        <joint name="joint2">
            <hardwareInterface>hardware_interface/PositionJointInterface</hardwareInterface>
        </joint>
        <actuator name="motor2">
            <hardwareInterface>hardware_interface/PositionJointInterface</hardwareInterface>
            <mechanicalReduction>1</mechanicalReduction>
        </actuator>
    </transmission>

    <transmission name="joint3_trans">
        <type>transmission_interface/SimpleTransmission</type>
        <joint name="joint3">
            <hardwareInterface>hardware_interface/PositionJointInterface</hardwareInterface>
        </joint>
        <actuator name="motor3">
            <hardwareInterface>hardware_interface/PositionJointInterface</hardwareInterface>
            <mechanicalReduction>1</mechanicalReduction>
        </actuator>
    </transmission>

    <transmission name="joint4_trans">
        <type>transmission_interface/SimpleTransmission</type>
        <joint name="joint4">
            <hardwareInterface>hardware_interface/PositionJointInterface</hardwareInterface>
        </joint>
        <actuator name="motor4">
            <hardwareInterface>hardware_interface/PositionJointInterface</hardwareInterface>
            <mechanicalReduction>1</mechanicalReduction>
        </actuator>
    </transmission>

    <transmission name="joint5_trans">
        <type>transmission_interface/SimpleTransmission</type>
        <joint name="joint5">
            <hardwareInterface>hardware_interface/PositionJointInterface</hardwareInterface>
        </joint>
        <actuator name="motor5">
            <hardwareInterface>hardware_interface/PositionJointInterface</hardwareInterface>
            <mechanicalReduction>1</mechanicalReduction>
        </actuator>
    </transmission>

    <transmission name="joint6_trans">
        <type>transmission_interface/SimpleTransmission</type>
        <joint name="joint6">
            <hardwareInterface>hardware_interface/PositionJointInterface</hardwareInterface>
        </joint>
        <actuator name="motor6">
            <hardwareInterface>hardware_interface/PositionJointInterface</hardwareInterface>
            <mechanicalReduction>1</mechanicalReduction>
        </actuator>
    </transmission>

</robot>
